<?xml version="1.0" encoding="UTF-8"?>
<!-- Generated by org.testng.reporters.JUnitReportReporter -->
<testsuite skipped="0" hostname="DESKTOP-FQ6DBV1" name="com.autotest.java.demo.testng.TestNGDemoTest" tests="4" failures="0" timestamp="2020-04-24T18:18:10 CST" time="0.010" errors="1">
  <testcase name="withMoreThanOneExceptionOfFNF" time="0.004" classname="com.autotest.java.demo.testng.TestNGDemoTest"/>
  <system-out/>
  <testcase name="withOneException" time="0.001" classname="com.autotest.java.demo.testng.TestNGDemoTest"/>
  <system-out/>
  <testcase name="withMoreThanOneExceptionOfArith" time="0.001" classname="com.autotest.java.demo.testng.TestNGDemoTest">
    <error type="org.testng.TestException" message="
Method TestNGDemoTest.withMoreThanOneExceptionOfArith()[pri:0, instance:com.autotest.java.demo.testng.TestNGDemoTest@77846d2c] should have thrown an exception of any of types [class java.io.FileNotFoundException, class java.lang.ArithmeticException]">
      <![CDATA[org.testng.TestException: 
Method TestNGDemoTest.withMoreThanOneExceptionOfArith()[pri:0, instance:com.autotest.java.demo.testng.TestNGDemoTest@77846d2c] should have thrown an exception of any of types [class java.io.FileNotFoundException, class java.lang.ArithmeticException]
at org.testng.internal.ExpectedExceptionsHolder.noException(ExpectedExceptionsHolder.java:78)
at org.testng.internal.TestInvoker.considerExceptions(TestInvoker.java:746)
at org.testng.internal.TestInvoker.invokeMethod(TestInvoker.java:634)
at org.testng.internal.TestInvoker.invokeTestMethod(TestInvoker.java:174)
at org.testng.internal.MethodRunner.runInSequence(MethodRunner.java:46)
at org.testng.internal.TestInvoker$MethodInvocationAgent.invoke(TestInvoker.java:821)
at org.testng.internal.TestInvoker.invokeTestMethods(TestInvoker.java:147)
at org.testng.internal.TestMethodWorker.invokeTestMethods(TestMethodWorker.java:146)
at org.testng.internal.TestMethodWorker.run(TestMethodWorker.java:128)
at java.util.ArrayList.forEach(ArrayList.java:1257)
at org.testng.TestRunner.privateRun(TestRunner.java:767)
at org.testng.TestRunner.run(TestRunner.java:588)
at org.testng.SuiteRunner.runTest(SuiteRunner.java:384)
at org.testng.SuiteRunner.runSequentially(SuiteRunner.java:378)
at org.testng.SuiteRunner.privateRun(SuiteRunner.java:337)
at org.testng.SuiteRunner.run(SuiteRunner.java:286)
at org.testng.SuiteRunnerWorker.runSuite(SuiteRunnerWorker.java:53)
at org.testng.SuiteRunnerWorker.run(SuiteRunnerWorker.java:96)
at org.testng.TestNG.runSuitesSequentially(TestNG.java:1214)
at org.testng.TestNG.runSuitesLocally(TestNG.java:1136)
at org.testng.TestNG.runSuites(TestNG.java:1066)
at org.testng.TestNG.run(TestNG.java:1034)
at org.testng.remote.AbstractRemoteTestNG.run(AbstractRemoteTestNG.java:115)
at org.testng.remote.RemoteTestNG.initAndRun(RemoteTestNG.java:251)
at org.testng.remote.RemoteTestNG.main(RemoteTestNG.java:77)
]]>
    </error>
  </testcase> <!-- withMoreThanOneExceptionOfArith -->
  <system-out/>
  <testcase name="testWithDependAlwaysSuccess" time="0.004" classname="com.autotest.java.demo.testng.TestNGDemoTest"/>
  <system-out/>
</testsuite> <!-- com.autotest.java.demo.testng.TestNGDemoTest -->
